Workbook

Sheet Data Order
A1: / | B1: No | C1: ID | D1: Tanggal | E1: Closing | F1: Nama | G1: Nama Usaha | H1: Jenis Usaha | I1: No Whatsapp Bisnis | J1: Deskripsi Produk Jasa | K1: Lokasi | L1: Usia | M1: Jenis Kelamin | N1: Durasi | O1: Mulai | P1: Selesai | Q1: Catatan | R1: ChatId | S1: Video Selesai | T1: Total Bayar | U1: CS | V1: System Date | W1: Nama Singkat | X1: Campaign Name | Y1: AccountId | Z1: Fanspage | AA1: Link Whatsapp | AB1: KampanyeId | AC1: LimitBudget | AD1: Advertiser | AE1: Kategori | AF1: Tanggal Up | AG1: Status Pembayaran
A2: Baru | B2: 1 | C2: ORD-1 | D2: 45779 | E2: 45792 | F2: Dummy | G2: Dummy | H2: Dummy | I2: 085777110340 | J2: Dummy | K2: Dummy | L2: 17-50 | M2: perempuan | N2: 0 | R2: -4633975755 | T2: 0 | V2: {=E2:E1726} -> 45792 | W2: =IFERROR(__xludf.DUMMYFUNCTION("ARRAYFORMULA(IF(G2:G1726="""", """", IFERROR(REGEXEXTRACT(G2:G1726, ""^(\S+\s+\S+)""), G2:G1726) )) "),"Dummy") -> Dummy | X2: {=IF(W2:W1726="", "", "ON-" & W2:W1726 & "-" & TEXT(V2:V1726, "DDMMYYYY") & "+" & N2:N1726 & "-" & I2:I1726)} -> ON-Dummy-15052025+0-085777110340
A3: Iklan Tidak Aktif | B3: 2 | C3: ORD-2 | D3: 45795 | E3: 45795 | F3: ni luh sukasih | G3: LK spa n beauty | H3: SPA | I3: 6282341426767 | J3: profesional family Spa di Denpasar | K3: Bali | L3: 21 sampai max | M3: laki laki dan perempuan | N3: 14 | R3: -4633975755 | T3: 500000 | U3: Devi | V3: 45795 | W3: =IFERROR(__xludf.DUMMYFUNCTION("""COMPUTED_VALUE"""),"LK spa") -> LK spa | X3: ON-LK spa-18052025+14-6282341426767 | Y3: R11-759724529202804 | Z3: Promo UMKM Bersama-R10-569094022964012 | AA3: {="https://wa.me/" & I3:I1726} -> https://wa.me/6282341426767
A4: Perpanjang | B4: 3 | C4: ORD-3 | D4: 45798 | E4: 45796 | F4: Veronika Da Costa | G4: Verrocosta | H4: Kosmetik | I4: 61459676831 | K4: Bebonuk | L4: 17 th ke atas | M4: laki-laki dan perempuan | N4: 10 | O4: 45850 | P4: 45859 | R4: -4633975755 | T4: 375000 | U4: Isna | V4: 45796 | W4: =IFERROR(__xludf.DUMMYFUNCTION("""COMPUTED_VALUE"""),"Verrocosta") -> Verrocosta | X4: ON-Verrocosta-19052025+10-61459676831 | Y4: R10-174904221976312 | Z4: Promo UMKM Bersama-R10-569094022964012 | AA4: https://wa.me/61459676831 | AB4: 120225346217950694
A5: Iklan Tidak Aktif | B5: 4 | C5: ORD-4 | D5: 45799 | E5: 45798 | F5: Karyatukang87 | G5: Karyatukang87 | H5: Furniture Interior | I5: 628872305953 | K5: semarang dan jawa tengah | L5: 21-65 | M5: semua jenis | N5: 5 | R5: -4633975755 | T5: 197000 | U5: Devi | V5: 45798 | W5: =IFERROR(__xludf.DUMMYFUNCTION("""COMPUTED_VALUE"""),"Karyatukang87") -> Karyatukang87 | X5: ON-Karyatukang87-21052025+5-628872305953 | AA5: https://wa.me/628872305953
A6: Iklan Tidak Aktif | B6: 5 | C6: ORD-5 | D6: 45799 | E6: 45797 | F6: Ni Luh Suparwati | G6: Glam Beauty Salon & Spa | H6: Salon Kecantikan | I6: 67076472864 | K6: Seputaran Bungkulan Kubutambahan, Air Sanih, Sampai Dengan Ponjok Batu Dan Seputaran Buleleng Singaraja Bali | L6: Semua Usia | M6: Laki-laki & perempuan | N6: 10 | R6: -4633975755 | T6: 375000 | U6: Isna | V6: 45797 | W6: =IFERROR(__xludf.DUMMYFUNCTION("""COMPUTED_VALUE"""),"Glam Beauty") -> Glam Beauty | X6: ON-Glam Beauty-20052025+10-67076472864 | AA6: https://wa.me/67076472864
A7: Iklan Tidak Aktif | B7: 6 | C7: ORD-6 | D7: 45799 | E7: 45798 | F7: Iwan | G7: Iwan Audio | H7: Audio Mobil Eropa | I7: 6285711307707 | K7: seluruh indonesia | L7: 25 th ke atas | M7: laki-laki dan perempuan | N7: 5 | R7: -4633975755 | T7: 197000 | U7: Isna | V7: 45798 | W7: =IFERROR(__xludf.DUMMYFUNCTION("""COMPUTED_VALUE"""),"Iwan Audio") -> Iwan Audio | X7: ON-Iwan Audio-21052025+5-6285711307707 | AA7: https://wa.me/6285711307707
A8: Iklan Tidak Aktif | B8: 7 | C8: ORD-7 | D8: 45802.75 | E8: 45802.75 | F8: Vita | G8: Seblak Prasmanan Vita | H8: Seblak Prasmanan | I8: 6285270469663 | K8: lampahan.lorong koramil bener meriah aceh | L8: bebas | M8: semua jenis | N8: 0 | R8: -4633975755 | T8: 50000 | U8: Isna | V8: 45802.75 | W8: =IFERROR(__xludf.DUMMYFUNCTION("""COMPUTED_VALUE"""),"Seblak Prasmanan") -> Seblak Prasmanan | X8: ON-Seblak Prasmanan-25052025+0-6285270469663 | AA8: https://wa.me/6285270469663
A9: Iklan Tidak Aktif | B9: 9 | C9: ORD-9 | D9: 45802.755 | E9: 45801 | F9: Nur Musvita Ayu | G9: AR Salon | H9: Salon | I9: 6285757607630 | K9: Makassar, Gowa, Maros | L9: 18 th ke atas | M9: perempuan | N9: 5 | R9: -4633975755 | T9: 197000 | U9: Isna | V9: 45801 | W9: =IFERROR(__xludf.DUMMYFUNCTION("""COMPUTED_VALUE"""),"AR Salon") -> AR Salon | X9: ON-AR Salon-24052025+5-6285757607630 | AA9: https://wa.me/6285757607630
A10: Iklan Tidak Aktif | B10: 10 | C10: ORD-10 | D10: 45802.765 | E10: 45801 | F10: Winda nainggolan | G10: Winda Tebus emas | H10: Tebus emas | I10: 62882015054720 | K10: Medan dan prapat | M10: Perempuan | N10: 5 | R10: -4633975755 | T10: 197000 | U10: Devi | V10: 45801 | W10: =IFERROR(__xludf.DUMMYFUNCTION("""COMPUTED_VALUE"""),"Winda Tebus") -> Winda Tebus | X10: ON-Winda Tebus-24052025+5-62882015054720 | AA10: https://wa.me/62882015054720
A11: Iklan Tidak Aktif | B11: 11 | C11: ORD-11 | D11: 45802.845 | E11: 45802.845 | F11: Juni meika | G11: zL beauty homecare | H11: salon perawatan | I11: 6281549409606 | K11: smarinda kota | L11: Semua usia | M11: wanita dan laki2 | N11: 7 | R11: -4633975755 | T11: 297000 | U11: Yuni | V11: 45802.845 | W11: =IFERROR(__xludf.DUMMYFUNCTION("""COMPUTED_VALUE"""),"zL beauty") -> zL beauty | X11: ON-zL beauty-25052025+7-6281549409606 | AA11: https://wa.me/6281549409606
A12: Iklan Tidak Aktif | B12: 12 | C12: ORD-12 | D12: 45803.851 | E12: 45802.845 | F12: ramli | G12: Eny Laundry | H12: Laundry karpet & Pakaian | I12: 6283129638348 | J12: laundry karpet, pakaian,sofa,boneka.profesional murah berkualitas, dan bergaransi (paling diutamakan karpet) | K12: lombok tengah | L12: 25ke atas | M12: perempuan | N12: 5 | R12: -4633975755 | T12: 197000 | U12: Yuni | V12: 45802.845 | W12: =IFERROR(__xludf.DUMMYFUNCTION("""COMPUTED_VALUE"""),"Eny Laundry") -> Eny Laundry | X12: ON-Eny Laundry-25052025+5-6283129638348 | AA12: https://wa.me/6283129638348
A13: Iklan Tidak Aktif | B13: 13 | C13: ORD-13 | D13: 45805.229 | E13: 45803 | F13: Adi | G13: AJP ADI | H13: PLAFON | I13: 6283188945188 | K13: Watukumpul Pemalang Jawa Tengah | L13: 20-65 | M13: laki-laki & perempuan | N13: 5 | R13: -4633975755 | T13: 197000 | U13: Isna | V13: 45803 | W13: =IFERROR(__xludf.DUMMYFUNCTION("""COMPUTED_VALUE"""),"AJP ADI") -> AJP ADI | X13: ON-AJP ADI-26052025+5-6283188945188 | AA13: https://wa.me/6283188945188
A14: Iklan Tidak Aktif | B14: 14 | C14: ORD-14 | D14: 45805.232 | E14: 45804 | F14: Yara | G14: M&Y mahkota salon & yara wedding | H14: wedding dan salon kecantikan | J14: wo wedding organizer juga salon kecantikan | K14: kalimantan selatan, kalimantan tengah, kalimantan timur | L14: 15-60 | M14: perempuan | N14: 5 | R14: -4633975755 | T14: 197000 | U14: Isna | V14: 45804 | W14: =IFERROR(__xludf.DUMMYFUNCTION("""COMPUTED_VALUE"""),"M&Y mahkota") -> M&Y mahkota | X14: ON-M&Y mahkota-27052025+5- | AA14: https://wa.me/
A15: Iklan Tidak Aktif | B15: 15 | C15: ORD-15 | D15: 45806.487 | E15: 45804 | F15: Mira Cantika | G15: Mira Cantika Makeup | H15: Makeup pengantin (MUA) | I15: 6285758792669 | K15: Tebo , Bungo, Sarolangun, Jambi | L15: 18th ke atas | M15: perempuan | N15: 5 | R15: -4633975755 | T15: 197000 | U15: Devi | V15: 45804 | W15: =IFERROR(__xludf.DUMMYFUNCTION("""COMPUTED_VALUE"""),"Mira Cantika") -> Mira Cantika | X15: ON-Mira Cantika-27052025+5-6285758792669 | AA15: https://wa.me/6285758792669
A16: Iklan Tidak Aktif | B16: 16 | C16: ORD-16 | D16: 45806.492 | E16: 45805 | F16: Lina Nalurita | G16: Khairan Wedding | H16: Salon perawatan rambut,wajah dan MUA | I16: 6285220903499 | K16: daerah Sumedang dan sekitarnya, Bandung | L16: SMP sd 60 thnan | M16: khusus wanita salonnya. | N16: 5 | R16: -4633975755 | T16: 197000 | U16: Devi | V16: 45805 | W16: =IFERROR(__xludf.DUMMYFUNCTION("""COMPUTED_VALUE"""),"Khairan Wedding") -> Khairan Wedding | X16: ON-Khairan Wedding-28052025+5-6285220903499 | AA16: https://wa.me/6285220903499
A17: Iklan Tidak Aktif | B17: 17 | C17: ORD-17 | D17: 45806.494 | E17: 45805 | F17: Neng Ay salon | G17: Neng Ay salon | H17: Salon | I17: 6282290353409 | K17: kota sorong dan manokwari | M17: khusus wanita | N17: 10 | R17: -4633975755 | T17: 375000 | U17: Devi | V17: 45805 | W17: =IFERROR(__xludf.DUMMYFUNCTION("""COMPUTED_VALUE"""),"Neng Ay") -> Neng Ay | X17: ON-Neng Ay-28052025+10-6282290353409 | AA17: https://wa.me/6282290353409
A18: Iklan Tidak Aktif | B18: 18 | C18: ORD-18 | D18: 45806.498 | E18: 45805 | F18: ISAL | G18: ISAL SALON | H18: PERAWATAN RAMBUT | I18: 6285240684331 | J18: Diskon 20% untuk Smoting dan warna rambut | K18: kendari | L18: semua usia | M18: laki-laki dan perempuan | N18: 5 | R18: -4633975755 | T18: 197000 | U18: Devi | V18: 45805 | W18: =IFERROR(__xludf.DUMMYFUNCTION("""COMPUTED_VALUE"""),"ISAL SALON") -> ISAL SALON | X18: ON-ISAL SALON-28052025+5-6285240684331 | AA18: https://wa.me/6285240684331
A19: Iklan Tidak Aktif | B19: 19 | C19: ORD-19 | D19: 45807.359 | E19: 45805 | F19: Devi Andesta | G19: Devy Kikim | H19: Salon & Wedding | I19: 6282136666049 | J19: semua keahlian salon sudah bersertifikasi BNSP sudah bersertifikasi mua level 3 bnsp | K19: jabodetabek | L19: semua usia | M19: pria & wanita | N19: 5 | R19: -4633975755 | T19: 197000 | U19: Isna | V19: 45805 | W19: =IFERROR(__xludf.DUMMYFUNCTION("""COMPUTED_VALUE"""),"Devy Kikim") -> Devy Kikim | X19: ON-Devy Kikim-28052025+5-6282136666049 | AA19: https://wa.me/6282136666049
A20: Iklan Tidak Aktif | B20: 20 | C20: ORD-20 | D20: 45807.363 | E20: 45805 | F20: Nyaraa | G20: Nyaraa Salon | H20: Salon | I20: 6282348365032 | K20: desa mattaropuli kecamatan bengo kabupaten bone soppeng dan wajo | L20: 10-35 | M20: perempuan | N20: 5 | R20: -4633975755 | T20: 197000 | U20: Isna | V20: 45805 | W20: =IFERROR(__xludf.DUMMYFUNCTION("""COMPUTED_VALUE"""),"Nyaraa Salon") -> Nyaraa Salon | X20: ON-Nyaraa Salon-28052025+5-6282348365032 | AA20: https://wa.me/6282348365032
A21: Iklan Tidak Aktif | B21: 21 | C21: ORD-21 | D21: 45807.742 | E21: 45807 | F21: M. Arif Sirajuddin | G21: Sunat Pangkep Avacare | H21: Jasa Sunat Modern | I21: 6285355435848 | K21: Kabupaten Pangkep Sulawesi Selatan | M21: pria | N21: 5 | R21: -4633975755 | T21: 297000 | U21: Yuni | V21: 45807 | W21: =IFERROR(__xludf.DUMMYFUNCTION("""COMPUTED_VALUE"""),"Sunat Pangkep") -> Sunat Pangkep | X21: ON-Sunat Pangkep-30052025+5-6285355435848 | AA21: https://wa.me/6285355435848
A22: Iklan Tidak Aktif | B22: 22 | C22: ORD-22 | D22: 45808.393 | E22: 45807 | F22: NURKHOLIS | G22: PUTRA MANDIRI HARMONIKA | H22: PRODUKSI PINTU BESI | I22: 6281331854948 | J22: spesialist pintu besi | K22: jombang, lamongan, sidoarjo, mojokerto, kediri | L22: 22-65 th | M22: semua jenis | N22: 10 | R22: -4633975755 | T22: 375000 | U22: Isna | V22: 45807 | W22: =IFERROR(__xludf.DUMMYFUNCTION("""COMPUTED_VALUE"""),"PUTRA MANDIRI") -> PUTRA MANDIRI | X22: ON-PUTRA MANDIRI-30052025+10-6281331854948 | AA22: https://wa.me/6281331854948
A23: Iklan Aktif | B23: 23 | C23: ORD-23 | D23: 45808.396 | E23: 45807 | F23: M. Ramli Zebua | G23: PT MAKMUR JAYA ZEBUA | H23: jasa tukang bangunan | I23: 6282173535013 | J23: jasa tukang bangunan rumah dan kontraktor di bidang pembangunan | K23: kota pekanbaru riau dan sekitarnya | L23: 35 th | M23: laki-laki | N23: 5 | R23: -4633975755 | T23: 197000 | U23: Isna | V23: 45807 | W23: =IFERROR(__xludf.DUMMYFUNCTION("""COMPUTED_VALUE"""),"PT MAKMUR") -> PT MAKMUR | X23: ON-PT MAKMUR-30052025+5-6282173535013 | AA23: https://wa.me/6282173535013 | AB23: 120227423725240200
A24: Iklan Tidak Aktif | B24: 24 | C24: ORD-24 | D24: 45808.4 | E24: 45807 | F24: Inggie | G24: Loundry W&M | H24: Londry | I24: 6288242107169 | J24: cuci kering setrika bisa antar jemput sesuai jarak | K24: dari bundaran samata kampus uin samata | L24: 35 th | M24: perempuan | N24: 5 | O24: 45811 | P24: 45815 | R24: -4633975755 | T24: 197000 | U24: Isna | V24: 45807 | W24: =IFERROR(__xludf.DUMMYFUNCTION("""COMPUTED_VALUE"""),"Loundry W&M") -> Loundry W&M | X24: ON-Loundry W&M-30052025+5-6288242107169 | Y24: R11-759724529202804 | Z24: Promo Bisnis UMKM-R11-672574572602431 | AA24: https://wa.me/6288242107169
A25: Iklan Tidak Aktif | B25: 25 | C25: ORD-25 | D25: 45808.76 | E25: 45802 | F25: Yara | G25: M&Y mahkota salon & yara wedding | H25: wedding & salon kecantikan | I25: 6282159148587 | K25: kalimantan selatan, kalimantan tengah, kalimantan timur | L25: 15-60 th | M25: perempuan | N25: 5 | R25: -4633975755 | T25: 197000 | U25: Isna | V25: 45802 | W25: =IFERROR(__xludf.DUMMYFUNCTION("""COMPUTED_VALUE"""),"M&Y mahkota") -> M&Y mahkota | X25: ON-M&Y mahkota-25052025+5-6282159148587 | AA25: https://wa.me/6282159148587
A26: Iklan Tidak Aktif | B26: 26 | C26: ORD-26 | D26: 45808.766 | E26: 45799 | F26: Lisa | G26: Lisa Beauty Zone | H26: Beauty Studio | I26: 6282314234523 | K26: Area Solo dan Sukoharjo, Jawa Tengah | L26: 18 th keatas | M26: Perempuan | N26: 5 | R26: -4633975755 | T26: 197000 | U26: Devi | V26: 45799 | W26: =IFERROR(__xludf.DUMMYFUNCTION("""COMPUTED_VALUE"""),"Lisa Beauty") -> Lisa Beauty | X26: ON-Lisa Beauty-22052025+5-6282314234523 | AA26: https://wa.me/6282314234523
A27: Iklan Tidak Aktif | B27: 27 | C27: ORD-27 | D27: 45809.405 | E27: 45808 | F27: Bogie Irawan | G27: Dapur Florist (Metro Lampung) | H27: Jasa Sewa Papan Bunga Premium | I27: 6281399998259 | J27: terima pesanan karangan bunga untuk acara wedding, duka cita, sertijab, pelantikan, ulang tahun, wisuda dll. | K27: kota metro, lampung timur, lampung tengah, bandar lampung, provinsi lampung. | L27: 15 th ke atas | M27: male n female | N27: 10 | O27: 45811 | P27: 45820 | R27: -4633975755 | T27: 375000 | U27: Isna | V27: 45808 | W27: =IFERROR(__xludf.DUMMYFUNCTION("""COMPUTED_VALUE"""),"Dapur Florist") -> Dapur Florist | X27: ON-Dapur Florist-31052025+10-6281399998259 | Y27: R11-759724529202804 | Z27: Promo Bisnis UMKM-R11-672574572602431 | AA27: https://wa.me/6281399998259
A28: Iklan Aktif | B28: 28 | C28: ORD-28 | D28: 45809.558 | E28: 45809.558 | F28: EPE Plavon | G28: EPE Plavon | H28: Pasang Plavon dan interior | I28: 6285362101860 | K28: Nias | M28: perempua dan laki laki | N28: 5 | O28: 45811 | P28: 45815 | R28: -4633975755 | T28: 197000 | U28: Devi | V28: 45809.558 | W28: =IFERROR(__xludf.DUMMYFUNCTION("""COMPUTED_VALUE"""),"EPE Plavon") -> EPE Plavon | X28: ON-EPE Plavon-01062025+5-6285362101860 | Y28: R10-174904221976312 | Z28: Pakar Bangun Indonesia-R11-706957285826722 | AA28: https://wa.me/6285362101860
A29: Iklan Tidak Aktif | B29: 29 | C29: ORD-29 | D29: 45809.56 | E29: 45809.558 | F29: Rina | G29: Klinik murabeautycare | H29: klinik kecantikan | I29: 6282274447649 | K29: Medan | L29: 15-65 tahun | M29: Laki laki dan perempuan | N29: 5 | R29: -4633975755 | T29: 197000 | U29: Devi | V29: 45809.558 | W29: =IFERROR(__xludf.DUMMYFUNCTION("""COMPUTED_VALUE"""),"Klinik murabeautycare") -> Klinik murabeautycare | X29: ON-Klinik murabeautycare-01062025+5-6282274447649 | AA29: https://wa.me/6282274447649 | AB29: 120228023839160200
A30: Iklan Tidak Aktif | B30: 30 | C30: ORD-30 | D30: 45809.689 | E30: 45809.558 | F30: Ali Rahman | G30: Sofie Gorden | H30: Usaha gorden | I30: 6282154795446 | J30: Jasa pembuatan gorden dan pemesanan gorden | K30: seluruh Kalimantan Timur | L30: 17 Tahun keatas | M30: perempuan dan laki laki | N30: 5 | R30: -4633975755 | T30: 197000 | U30: Yuni | V30: 45809.558 | W30: =IFERROR(__xludf.DUMMYFUNCTION("""COMPUTED_VALUE"""),"Sofie Gorden") -> Sofie Gorden | X30: ON-Sofie Gorden-01062025+5-6282154795446 | AA30: https://wa.me/6282154795446
A31: Iklan Tidak Aktif | B31: 32 | C31: ORD-32 | D31: 45809.826 | E31: 45809.558 | F31: irsyad a gani | G31: icad Interior | H31: kitchen set interior | I31: 6285211510282 | K31: jakarta, tangerang | L31: 25 - 45 | M31: wanita | N31: 5 | R31: -4633975755 | T31: 197000 | U31: Devi | V31: 45809.558 | W31: =IFERROR(__xludf.DUMMYFUNCTION("""COMPUTED_VALUE"""),"icad Interior") -> icad Interior | X31: ON-icad Interior-01062025+5-6285211510282 | AA31: https://wa.me/6285211510282
A32: Iklan Tidak Aktif | B32: 33 | C32: ORD-33 | D32: 45810.567 | E32: 45809 | F32: umam | G32: sahabat AC malang | H32: servis ac | I32: 6285737244570 | J32: servis AC untuk wilayah malang,harga terjangkau, pasti puas bergaransi | K32: malang Jawa timur | L32: 25++ | M32: perempuan dan laki-laki | N32: 5 | O32: 45811 | P32: 45815 | R32: -4633975755 | T32: 197 | U32: Yuni | V32: 45809 | W32: =IFERROR(__xludf.DUMMYFUNCTION("""COMPUTED_VALUE"""),"sahabat AC") -> sahabat AC | X32: ON-sahabat AC-01062025+5-6285737244570 | Y32: R11-759724529202804 | Z32: Pakar Teknisi-R11-696512170212149 | AA32: https://wa.me/6285737244570
A33: Iklan Tidak Aktif | B33: 34 | C33: ORD-34 | D33: 45810.597 | E33: 45809 | F33: Ngatini | G33: Travel Umroh dan Haji | H33: Samira Travel Pati | I33: 6285290626929 | K33: pati dan sekitarnya | L33: 30 ke atas | M33: pria dan wanita | N33: 5 | O33: 45811 | P33: 45816 | R33: -4633975755 | T33: 197000 | U33: Isna | V33: 45809 | W33: =IFERROR(__xludf.DUMMYFUNCTION("""COMPUTED_VALUE"""),"Travel Umroh") -> Travel Umroh | X33: ON-Travel Umroh-01062025+5-6285290626929 | Y33: R11-759724529202804 | Z33: Promo Bisnis UMKM-R11-672574572602431 | AA33: https://wa.me/6285290626929
A34: Iklan Tidak Aktif | B34: 35 | C34: ORD-35 | D34: 45810.617 | E34: 45809 | F34: Joko Susilo | G34: bengkel mobil sahaja pelita jaya(SPJ) | H34: perbaikan dan layanan jasa Mobil | I34: 6282288123215 | K34: sukarame,Sukabumi,korpri,jati agung, | L34: 18+ | M34: laki-laki dan perempuan | N34: 10 | R34: -4633975755 | T34: 375000 | U34: Yuni | V34: 45809 | W34: =IFERROR(__xludf.DUMMYFUNCTION("""COMPUTED_VALUE"""),"bengkel mobil") -> bengkel mobil | X34: ON-bengkel mobil-01062025+10-6282288123215 | Y34: R06-766589657993298 | Z34: Sahabat Otomotif-R11-645488418650292 | AA34: https://wa.me/6282288123215
A35: Iklan Tidak Aktif | B35: 36 | C35: ORD-36 | D35: 45810.656 | E35: 45809 | F35: Ahmad Bukhori | G35: Dani Interior | H35: interior | I35: 6281384925770 | J35: menerima pesanan kitchen set, backdrop tv, penyekat ruangan, lemari,tolet/meja rias,meja kantor, partisi,meja belajar dll | K35: Sukolilo Pati, Jateng | L35: 18 tahun keatas | M35: perempuan dan laki-laki | N35: 5 | O35: 45813 | P35: 45817 | R35: -4633975755 | T35: 197000 | U35: Yuni | V35: 45809 | W35: =IFERROR(__xludf.DUMMYFUNCTION("""COMPUTED_VALUE"""),"Dani Interior") -> Dani Interior | X35: ON-Dani Interior-01062025+5-6281384925770 | Y35: R06-766589657993298 | Z35: Pakar Bangun Indonesia-R11-706957285826722 | AA35: https://wa.me/6281384925770
A36: Iklan Tidak Aktif | B36: 38 | C36: ORD-38 | D36: 45810.79 | E36: 45810 | F36: Waldy | G36: Yuzef & Kost Homestay Syariah | H36: Kost2an | I36: 628988759290 | J36: yuzef kost harian & bulanan | K36: dekat dengan SMA Taruna, Stikes Payung Negeri Poltekes Riau | L36: 15-23 th | M36: wanita | N36: 13 | O36: 45813 | P36: 45825 | R36: -4633975755 | T36: 500000 | U36: Isna | V36: 45810 | W36: =IFERROR(__xludf.DUMMYFUNCTION("""COMPUTED_VALUE"""),"Yuzef &") -> Yuzef & | X36: ON-Yuzef &-02062025+13-628988759290 | Y36: R10-174904221976312 | Z36: Promo Bisnis UMKM-R11-672574572602431 | AA36: https://wa.me/628988759290 | AB36: 120226464082810694
A37: Iklan Tidak Aktif | B37: 38 | C37: ORD-38 | D37: 45810.895 | E37: 45810 | F37: Darmawan | G37: Pakis Advertising & Kontruksi | H37: Pakis Advertising Menerima pesanan pengerjaan | I37: 6281934079192 | J37: Menerima pesanan pengerjaan | K37: Pekanbaru | L37: 25 keatas | M37: Perempuan & laki2 | N37: 7 | O37: 45812 | R37: -4633975755 | T37: 297000 | U37: Yuni | V37: 45810 | W37: =IFERROR(__xludf.DUMMYFUNCTION("""COMPUTED_VALUE"""),"Pakis Advertising") -> Pakis Advertising | X37: ON-Pakis Advertising-02062025+7-6281934079192 | Y37: R11-759724529202804 | Z37: Promo Bisnis UMKM-R11-672574572602431 | AA37: https://wa.me/6281934079192
A38: Iklan Tidak Aktif | B38: 39 | C38: ORD-39 | D38: 45811.605 | E38: 45810 | F38: ike ria jelita | G38: Griya rias jelita salon | H38: salon dan rias pengantin | I38: 6281335551395 | J38: salon kecantikan dan rias pengantin | K38: Jetis, Mojokerto | L38: 18 tahun keatas | N38: 5 | O38: 45813 | P38: 45817 | R38: -4633975755 | T38: 197000 | U38: Yuni | V38: 45810 | W38: =IFERROR(__xludf.DUMMYFUNCTION("""COMPUTED_VALUE"""),"Griya rias") -> Griya rias | X38: ON-Griya rias-02062025+5-6281335551395 | Y38: R10-174904221976312 | Z38: Beauty Solution-R11-667346859796665 | AA38: https://wa.me/6281335551395
A39: Iklan Tidak Aktif | B39: 40 | C39: ORD-40 | D39: 45811.605 | E39: 45811.605 | F39: Fit Klin | G39: Fit Klin | H39: Fit Klin | I39: 6282350524788 | N39: 30 | O39: 45811 | P39: 45841 | T39: 875000 | U39: Rudi | V39: 45811.605 | W39: =IFERROR(__xludf.DUMMYFUNCTION("""COMPUTED_VALUE"""),"Fit Klin") -> Fit Klin | X39: ON-Fit Klin-03062025+30-6282350524788 | Y39: R11-759724529202804 | Z39: Promo Bisnis UMKM-R11-672574572602431 | AA39: https://wa.me/6282350524788 | AB39: 120227782745500200
A40: Iklan Tidak Aktif | B40: 43 | C40: ORD-43 | D40: 45812.184 | E40: 45811.605 | F40: M Budiman | G40: CV Budi Mulia Berkah | H40: konstruksi bangunan | I40: 6285822386125 | J40: kontruksi bangunan | K40: Pontianak | L40: 18 tahun keatas | M40: laki-laki dan perempuan | N40: 5 | O40: 45813 | P40: 45817 | R40: -4633975755 | T40: 197000 | U40: Yuni | V40: 45811.605 | W40: =IFERROR(__xludf.DUMMYFUNCTION("""COMPUTED_VALUE"""),"CV Budi") -> CV Budi | X40: ON-CV Budi-03062025+5-6285822386125 | Y40: R06-766589657993298 | Z40: Pakar Bangun Indonesia-R11-706957285826722 | AA40: https://wa.me/6285822386125
...

Sheet Log
A1: 45975.534 | B1: Trigger: #inputlaporan# Laporan CS Jasa Iklan UMKM ------- Nama CS: Isna Tanggal: 13-Nov-2025 Leads:60 Jumlah Closing: Paket 1: Paket 2: Paket 3: Paket 4: Paket 5: Repeat Paket 1: Repeat Paket 2: Repeat Paket 3: Repeat Paket 4: Repeat Paket 5: Catatan: 26 nores 18 cek harga 10 tanya tanya 5 isi data 1 ngga jadi
A2: 45975.534 | B2: ERROR: ReferenceError: parseLaporanCS is not defined
A3: 45975.537 | B3: Trigger: #inputlaporan# Laporan CS Jasa Iklan UMKM ------- Nama CS: Isna Tanggal: 13-Nov-2025 Leads:60 Jumlah Closing: Paket 1: Paket 2: Paket 3: Paket 4: Paket 5: Repeat Paket 1: Repeat Paket 2: Repeat Paket 3: Repeat Paket 4: Repeat Paket 5: Catatan: 26 nores 18 cek harga 10 tanya tanya 5 isi data 1 ngga jadi
A4: 45975.537 | B4: Exception: De parameters (String,String,String) komen niet overeen met de methodehandtekening voor Utilities.formatDate.
A5: 45975.537 | B5: LAPORAN SAVED: false
A6: 45975.538 | B6: Trigger: #inputlaporan# Laporan CS Jasa Iklan UMKM ------- Nama CS: Isna Tanggal: 13-Nov-2025 Leads:60 Jumlah Closing: Paket 1: Paket 2: Paket 3: Paket 4: Paket 5: Repeat Paket 1: Repeat Paket 2: Repeat Paket 3: Repeat Paket 4: Repeat Paket 5: Catatan: 26 nores 18 cek harga 10 tanya tanya 5 isi data 1 ngga jadi
A7: 45975.538 | B7: Exception: De parameters (String,String,String) komen niet overeen met de methodehandtekening voor Utilities.formatDate.
A8: 45975.538 | B8: LAPORAN SAVED: false
A9: 45976.387 | B9: Trigger: /start
A10: 45976.388
A11: 45976.389
A12: 45976.389
A13: 45976.389
A14: 45976.398
A15: 45976.407
A16: 45976.415
A17: 45976.422
A18: 45976.466 | B18: Trigger: /start
A19: 45976.468 | B19: Trigger: #inputorder# Data Pesanan Jasa Iklan UMKM Data Pemesan ---- Tanggal: 15-Nov-2025 Nama: Para Ir. Berpengalaman Nama Usaha: PT. Panorama Jaya Labana Jenis Usaha: Usaha Jasa Konstruksi spesialist bangun / renovasi Rumah No Whatsapp Bisnis: 628122102657 Alamat usaha: Bandung Deskripsi produk/jasa: AHLI BANGUNAN KAMI YANG BERGERAK DIBIDANG JASA PROPERTY DAN KONTRUKSI JASA BANGUN RUMAH, RENOVASI PROFESIONAL , INT,ERIOR DESN ANDA BUTUH RENOVASI RUMAH ATAU BANGUN RUMAH?? DENGAN DESAIN GAMBAR SERTA RencanaAnggaran Biaya (RAB). KAMI SIAP MEMBANTU ANDA!!! Jasa Kontraktor, Konstruksi, Bangun Baru Bangunan,Rumah tinggal, kos-kosan, kantor, tempat usaha, ruko, cafe,rumah butik, rumah kantor, rumah gudang/pabrik dll. Free: – Konsultasi arsitek & sipil bangunan – Desain arsitektur 3D – Gambar kerja lengkap – Sket denah ruangan dan interior – RAB Harga berdasarkan RAB bisa disesuaikan budget berdasar rencana gambar setelah survey lokasi dan atau konsultasi Perkiraan: Rumah sederhana: 3,2 Jt/m2 s.d. 3.5 Jt/m2 Rumah mewah (1 Lantai): 3.6 Jt/m2 s.d. 4,0 Jt/m2 Rumah mewah (2 Lantai): 4,2 Jt/m2 s.d. 5,0 Jt/m2 Rumah exclusive: lebih dari 5,0 Jt/m2 Juga melayani: – Renovasi dan Perbaikan bangunan – Jasa Desain Eksterior (Gambar Kerja Bangunan), Gambar Syarat IMB, Gambar 3D, Hitung Struktur, RAB | Perencanaan – Jasa Desain Interior dan Pembuatan Custom Furniture – Jasa penambahan ruang / pengalihan ruang seperti garasi menjadi butik, rumah menjadi rumah butik KONSULTASI dan SURVEY LOKASI GRATISS masalah harga NEGOTIABLE Data Target Iklan ---- Lokasi: Bandung,Jawa barat, seluruh Indonesia Usia: 17-55 Jenis kelamin:SU Data iklan ---- Durasi:14 Data Pembayaran ---- Total Bayar: 500000 Cs: Yuni Status: Perpanjang
A20: 45976.468 | B20: Memeriksa nomor WA setelah dibersihkan: '628122102657' (Tipe: string)
A21: 45976.468 | B21: Hasil validasi: Valid
A22: 45976.468 | B22: ORDER SAVED: ORD-1512
A23: 45976.478 | B23: Trigger: #inputorder# Data Pesanan Jasa Iklan UMKM Data Pemesan ---- Tanggal: 14-Nov-2025 Nama: Ali Imron Nama Usaha: Sinar Gorden Interior Jenis Usaha: Gorden, wallpaper, kaca film, flooring No Whatsapp Bisnis: 628156626447 Alamat: Jl Kol HR Hadijanto Banaran Sekaran Gunungpati Semarang Durasi: 14 Deskripsi produk/jasa: *Keunggulan usaha (wajib):*Gorden ukuran custom, gratis survey, konsultasi, pemasangan *keunikan usaha (wajib):* Banyak pilihan jenis motif dan warna. Kualitas bagus, harga bersahabat Promo: -Roller Blinds Harga mulai Rp.400.000 permeter persegi -Vertical Blinds Harga mulai Rp.300.000 permeter persegi -Venetian Blinds Mulai harga Rp.300.000 permeter persegi -Paket Super A : Jendela Lebar 130 - 160 cm Spesifikasi : - Gorden Blackout (L 200 cm T maks 300 cm) x 2 pcs - Vitrase L 320 cm T 300 cm - Roulet (pipa) tebal P 160 cm - Rel kotak tebal P 160 cm - Tali dan Gantungan - Free antar dan pasang ~Rp.1.300.000~ Rp.1.200.000 Gratis Survey Area Semarang dan sekitarnya Data Target Iklan ---- Lokasi: Semarang, Ungaran Usia: 25-60 th Jenis kelamin: laki-laki dan perempuan Data Pembayaran ---- Total Bayar: 550000 Cs: Isna Status: Baru
A24: 45976.478 | B24: Memeriksa nomor WA setelah dibersihkan: '628156626447' (Tipe: string)
A25: 45976.478 | B25: Hasil validasi: Valid
A26: 45976.478 | B26: ORDER SAVED: ORD-1513
A27: 45976.478 | B27: Trigger: #inputorder# Data Pesanan Jasa Iklan UMKM Data Pemesan ---- Tanggal: 14-Nov-2025 Nama: Sumini Mitro Suwarno Nama Usaha: Rumah Sehat Tradisional Holistic "AZELA" Jenis Usaha: Kesehatan Tradisional No Whatsapp Bisnis: 6281316122975 Alamat: Ruko Megalegenda 2 Blok D3 no 15 Batam Center Durasi: 7 Deskripsi produk/jasa: Menangani patah tulang, treatment perut + masker, treatment pasca melahirkan, lulur/body scrub, pijat tradisional, perawatan stroke, bekam tanduk, bekam api, hijamah dll Data Target Iklan ---- Lokasi: Batam Usia: semua umur Jenis kelamin: laki-laki dan perempuan Data Pembayaran ---- Total Bayar: 297000 Cs: Isna Status: Perpanjang
A28: 45976.478 | B28: Memeriksa nomor WA setelah dibersihkan: '6281316122975' (Tipe: string)
A29: 45976.478 | B29: Hasil validasi: Valid
... A65: 45976.804 | B65: ERROR: Exception: The data you entered in cell U1524 violates the data validation rules set on this cell. Please enter one of the following values: Isna, Devi, Yuni, Rudi, Jeff, Ilham, Rokhma, Maya, Tika.
A66: 45977.231
A67: 45977.231
A68: 45977.232
A69: 45977.232
A70: 45977.24
A71: 45977.245
A72: 45977.252
A73: 45977.258
A74: 45977.291 | B74: Trigger: #inputlaporan# Laporan CS Jasa Iklan UMKM ------- Nama CS: Yuni Tanggal: 15-Nov-2025 Leads: Jumlah Closing: 1 Paket 1: Paket 2: Paket 3: Paket 4: Paket 5: Repeat Paket 1: Repeat Paket 2: Repeat Paket 3: 1 Repeat Paket 4: Repeat Paket 5: Catatan:
A75: 45977.291 | B75: Exception: De parameters (String,String,String) komen niet overeen met de methodehandtekening voor Utilities.formatDate.
...

Sheet Performa Iklan Klien
A1: AkunIklanId | B1: NamaAkun | C1: KampanyeId | D1: Nama Usaha | E1: Whatsapp | F1: Tanggal | G1: Reach | H1: CPM | I1: LinkKlik | J1: Spend | K1: KlikWA | L1: VideoView | M1: Komentar | N1: Nama Kampanye | O1: Column 1
A2: 759724529202804 | B2: R11 | C2: 120227433380380200 | D2: Sunat Pangkep Avacare | E2: 6285255435848 | F2: 45809 | G2: 111 | H2: 6973.2143 | I2: 0 | J2: 781 | K2: 0 | L2: 41 | M2: 0 | N2: ON-Sunat Pangkep Avacare-02062025+7-6285255435848-ilham
A3: 759724529202804 | B3: R11 | C3: 120227432781140200 | D3: PUTRA MANDIRI HARMONIKA | E3: 6281331854948 | F3: 45809 | G3: 114 | H3: 11786.325 | I3: 0 | J3: 1379 | K3: 0 | L3: 37 | M3: 0 | N3: ON-PUTRA MANDIRI HARMONIKA-02062025+10-6281331854948-ilham
A4: 759724529202804 | B4: R11 | C4: 120227429269270200 | D4: Nyaraa Salon | E4: 6282348365032 | F4: 45809 | G4: 105 | H4: 11055.046 | I4: 4 | J4: 1205 | K4: 0 | L4: 29 | M4: 0 | N4: ON-Nyaraa Salon-02062025+5-6282348365032-ilham
A5: 759724529202804 | B5: R11 | C5: 120227423725240200 | D5: PT MAKMUR JAYA ZEBUA | E5: 6285220903499 | F5: 45809 | G5: 569 | H5: 17272.595 | I5: 23 | J5: 11849 | K5: 6 | L5: 278 | M5: 0 | N5: ON-PT MAKMUR JAYA ZEBUA-01062025+5-6285220903499-ilham
A6: 759724529202804 | B6: R11 | C6: 120227403909070200 | D6: khairan Wedding, Hair and Beauty | F6: 45809 | G6: 11726 | H6: 1260.1054 | I6: 19 | J6: 15057 | K6: 0 | L6: 1423 | M6: 0 | N6: ON-khairan Wedding, Hair and Beauty-01062025+6285220903499-ilham
A7: 759724529202804 | B7: R11 | C7: 120227400653870200 | D7: ISAL SALON | E7: 6285240684331 | F7: 45809 | G7: 1006 | H7: 12147.126 | I7: 22 | J7: 15852 | K7: 3 | L7: 228 | M7: 0 | N7: ON-ISAL SALON-01062025+5-6285240684331-ilham
A8: 759724529202804 | B8: R11 | C8: 120227397964810200 | D8: Neng Ay salon | E8: 6282154483973 | F8: 45809 | G8: 1510 | H8: 7866.3814 | I8: 30 | J8: 16543 | K8: 4 | L8: 418 | M8: 0 | N8: ON-Neng Ay salon-01062025+10-6282154483973-ilham
A9: 759724529202804 | B9: R11 | C9: 120227358608350200 | D9: Artha Jaya | E9: 6285757057088 | F9: 45809 | G9: 1031 | H9: 10509.921 | I9: 46 | J9: 15891 | K9: 2 | L9: 1 | M9: 1 | N9: ON-Artha Jaya-30052025+30-6285757057088
A10: 759724529202804 | B10: R11 | C10: 120227357012290200 | D10: Devy Kikim Salon & Wedding Organizer | E10: 6282136666049 | F10: 45809 | G10: 955 | H10: 14038.324 | I10: 23 | J10: 15751 | K10: 4 | L10: 275 | M10: 0 | N10: ON-Devy Kikim Salon & Wedding Organizer-31052025+5-6282136666049-ilham
A11: 759724529202804 | B11: R11 | C11: 120227286789550200 | D11: Eny M&Y mahkota salon & yara wedding | E11: 6282159148587 | F11: 45809 | G11: 713 | H11: 16799.534 | I11: 12 | J11: 14414 | K11: 1 | L11: 280 | M11: 0 | N11: ON-Eny M&Y mahkota salon & yara wedding-29052025+5-6282159148587-ilham
A12: 759724529202804 | B12: R11 | C12: 120227218075240200 | D12: AJP.ADI JAYA PLAFON | F12: 45809 | G12: 2 | H12: 12500 | I12: 0 | J12: 25 | K12: 0 | L12: 1 | M12: 0 | N12: ON-AJP.ADI JAYA PLAFON
A13: 759724529202804 | B13: R11 | C13: 120227217218600200 | D13: Eny Laundry karpet & Pakaian | E13: 6283129638348 | F13: 45809 | G13: 31 | H13: 11903.226 | I13: 0 | J13: 369 | K13: 0 | L13: 11 | M13: 0 | N13: ON-Eny Laundry karpet & Pakaian -28052025+5-6283129638348-ilham
A14: 759724529202804 | B14: R11 | C14: 120227215523910200 | D14: zL beauty homecare | E14: 6281549409606 | F14: 45809 | G14: 201 | H14: 22356.164 | I14: 3 | J14: 4896 | K14: 0 | L14: 62 | M14: 0 | N14: ON-zL beauty homecare -27052025+5-6281549409606-ilham
A15: 174904221976312 | B15: R10 | C15: 120225732846460694 | D15: SMA Madina | E15: 6281348555887 | F15: 45809 | G15: 1273 | H15: 8368.0104 | I15: 51 | J15: 12870 | K15: 5 | L15: 498 | M15: 1 | N15: ON-SMA Madina-29052025+20-6281348555887
A16: 174904221976312 | B16: R10 | C16: 120225732456000694 | D16: Aurora Teknik | E16: 6285376667233 | F16: 45809 | G16: 1133 | H16: 9910.7143 | I16: 27 | J16: 13320 | K16: 5 | L16: 402 | M16: 2 | N16: ON-Aurora Teknik-29052025+5-6285376667233
A17: 174904221976312 | B17: R10 | C17: 120225711165240694 | D17: Bang Banten | E17: 6282172291579 | F17: 45809 | G17: 897 | H17: 12435.455 | I17: 44 | J17: 13679 | K17: 6 | L17: 538 | M17: 0 | N17: ON-Bang Banten-31042025+10-6282172291579-Rudi
A18: 174904221976312 | B18: R10 | C18: 120225575002440694 | D18: Toko Emas Sembiring | E18: 6281263113266 | F18: 45809 | G18: 1507 | H18: 8065.6214 | I18: 60 | J18: 13889 | K18: 5 | L18: 746 | M18: 0 | N18: ON-Toko Emas Sembiring-15052025+30-6281263113266-Ilham - 2 - RCVR
A19: 174904221976312 | B19: R10 | C19: 120225346217950694 | D19: Verrocosta | E19: 6282226594414 | F19: 45809 | G19: 3350 | H19: 3210.4867 | I19: 146 | J19: 12797 | K19: 21 | L19: 1001 | M19: 4 | N19: ON-Verrocosta-23052025+10-6282226594414-ilham - Copy
A20: 174904221976312 | B20: R10 | C20: 120225230850710694 | D20: CV MZ banyu agung | E20: 62882001677470 | F20: 45809 | G20: 538 | H20: 20453.507 | I20: 17 | J20: 12538 | K20: 3 | L20: 226 | M20: 1 | N20: ON-CV MZ banyu agung-29052025+5-62882001677470-ilham
A21: 174904221976312 | B21: R10 | C21: 120225065069670694 | D21: LK spa n beauty | E21: 6282341426767 | F21: 45809 | G21: 354 | H21: 22997.674 | I21: 18 | J21: 9889 | K21: 5 | L21: 89 | M21: 0 | N21: ON-LK spa n beauty-19052025+14-6282341426767-ilham
A22: 759724529202804 | B22: R11 | C22: 120227459128820200 | D22: Karya Tukang | E22: 628872305953 | F22: 45810 | G22: 273 | H22: 39841.935 | I22: 3 | J22: 12351 | K22: 0 | L22: 77 | M22: 0 | N22: ON-Karya Tukang-25052025+5-628872305953-ilham - Copy
A23: 759724529202804 | B23: R11 | C23: 120227433380380200 | D23: Sunat Pangkep Avacare | E23: 6285255435848 | F23: 45810 | G23: 1046 | H23: 10273.894 | I23: 12 | J23: 14404 | K23: 3 | L23: 528 | M23: 0 | N23: ON-Sunat Pangkep Avacare-02062025+7-6285255435848-ilham
A24: 759724529202804 | B24: R11 | C24: 120227432781140200 | D24: PUTRA MANDIRI HARMONIKA | E24: 6281331854948 | F24: 45810 | G24: 696 | H24: 14277.19 | I24: 25 | J24: 14834 | K24: 3 | L24: 370 | M24: 0 | N24: ON-PUTRA MANDIRI HARMONIKA-02062025+10-6281331854948-ilham
... A26: 759724529202804 | B26: R11 | C26: 120227423725240200 | D26: PT MAKMUR JAYA ZEBUA | E26: 6285220903499 | F26: 45810 | G26: 754 | H26: 14830.439 | I26: 24 | J26: 14519 | K26: 1 | L26: 329 | M26: 0 | N26: ON-PT MAKMUR JAYA ZEBUA-01062025+5-6285220903499-ilham
A27: 759724529202804 | B27: R11 | C27: 120227403909070200 | D27: khairan Wedding, Hair and Beauty | F27: 45810 | G27: 11368 | H27: 1225.982 | I27: 16 | J27: 14420 | K27: 0 | L27: 1175 | M27: 0 | N27: ON-khairan Wedding, Hair and Beauty-01062025+6285220903499-ilham
A28: 759724529202804 | B28: R11 | C28: 120227400653870200 | D28: ISAL SALON | E28: 6285240684331 | F28: 45810 | G28: 944 | H28: 13401.603 | I28: 31 | J28: 15050 | K28: 6 | L28: 201 | M28: 3 | N28: ON-ISAL SALON-01062025+5-6285240684331-ilham
A29: 759724529202804 | B29: R11 | C29: 120227397964810200 | D29: Neng Ay salon | E29: 6282154483973 | F29: 45810 | G29: 1610 | H29: 7142.3407 | I29: 33 | J29: 15806 | K29: 3 | L29: 421 | M29: 1 | N29: ON-Neng Ay salon-01062025+10-6282154483973-ilham
A30: 759724529202804 | B30: R11 | C30: 120227358608350200 | D30: Artha Jaya | E30: 6285757057088 | F30: 45810 | G30: 1295 | H30: 8111.6585 | I30: 48 | J30: 14820 | K30: 6 | L30: 0 | M30: 0 | N30: ON-Artha Jaya-30052025+30-6285757057088
A31: 759724529202804 | B31: R11 | C31: 120227357012290200 | D31: Devy Kikim Salon & Wedding Organizer | E31: 6282136666049 | F31: 45810 | G31: 726 | H31: 18214.452 | I31: 18 | J31: 15628 | K31: 2 | L31: 239 | M31: 0 | N31: ON-Devy Kikim Salon & Wedding Organizer-31052025+5-6282136666049-ilham
A32: 759724529202804 | B32: R11 | C32: 120227286789550200 | D32: Eny M&Y mahkota salon & yara wedding | E32: 6282159148587 | F32: 45810 | G32: 1311 | H32: 8927.4093 | I32: 13 | J32: 14266 | K32: 0 | L32: 428 | M32: 0 | N32: ON-Eny M&Y mahkota salon & yara wedding-29052025+5-6282159148587-ilham
A33: 759724529202804 | B33: R11 | C33: 120227218075240200 | D33: AJP.ADI JAYA PLAFON | F33: 45810 | G33: 716 | H33: 17576.651 | I33: 20 | J33: 14905 | K33: 2 | L33: 190 | M33: 0 | N33: ON-AJP.ADI JAYA PLAFON
A34: 174904221976312 | B34: R10 | C34: 120225943524550694 | D34: Dapur Florist | E34: 6281399998259 | F34: 45810 | G34: 220 | H34: 10638.393 | I34: 6 | J34: 2383 | K34: 0 | L34: 92 | M34: 0 | N34: ON-Dapur Florist-03062025+10-6281399998259-ilham
A35: 174904221976312 | B35: R10 | C35: 120225924609850694 | D35: Amanah Interior | E35: 6282183184641 | F35: 45810 | G35: 1309 | H35: 8815.0773 | I35: 36 | J35: 13681 | K35: 3 | L35: 387 | M35: 0 | N35: ON- Amanah Interior-21052025+5-6282183184641 -ilham - NEW
A36: 174904221976312 | B36: R10 | C36: 120225732846460694 | D36: SMA Madina | E36: 6281348555887 | F36: 45810 | G36: 1360 | H36: 7290.4509 | I36: 31 | J36: 10994 | K36: 1 | L36: 457 | M36: 1 | N36: ON-SMA Madina-29052025+20-6281348555887
A37: 174904221976312 | B37: R10 | C37: 120225732456000694 | D37: Aurora Teknik | E37: 6285376667233 | F37: 45810 | G37: 1284 | H37: 9392.2652 | I37: 20 | J37: 13600 | K37: 3 | L37: 386 | M37: 0 | N37: ON-Aurora Teknik-29052025+5-6285376667233
A38: 174904221976312 | B38: R10 | C38: 120225711165240694 | D38: Bang Banten | E38: 6282172291579 | F38: 45810 | G38: 1066 | H38: 10798.038 | I38: 40 | J38: 13206 | K38: 6 | L38: 611 | M38: 0 | N38: ON-Bang Banten-31042025+10-6282172291579-Rudi
A39: 174904221976312 | B39: R10 | C39: 120225575002440694 | D39: Toko Emas Sembiring | E39: 6281263113266 | F39: 45810 | G39: 1205 | H39: 8665.6739 | I39: 45 | J39: 11638 | K39: 4 | L39: 553 | M39: 0 | N39: ON-Toko Emas Sembiring-15052025+30-6281263113266-Ilham - 2 - RCVR
A40: 174904221976312 | B40: R10 | C40: 120225366947220694 | D40: LPK ERBANSA AKADEMI | E40: 6282226594414 | F40: 45810 | G40: 1044 | H40: 12229.623 | I40: 29 | J40: 13954 | K40: 1 | L40: 262 | M40: 0 | N40: ON-LPK ERBANSA AKADEMI-25052025+5-6282226594414-ilham - Copy
A41: 174904221976312 | B41: R10 | C41: 120225346217950694 | D41: Verrocosta | E41: 6282226594414 | F41: 45810 | G41: 716 | H41: 2914.8649 | I41: 35 | J41: 2157 | K41: 6 | L41: 165 | M41: 0 | N41: ON-Verrocosta-23052025+10-6282226594414-ilham - Copy
...

Sheet Performa Iklan
A1: AkunIklanId | B1: NamaAkun | C1: KampanyeId | D1: KampanyeName | E1: Tanggal | F1: Reach | G1: CPM | H1: LinkKlik | I1: Budget | J1: KlikWhatsapp | K1: VideoView | L1: Komentar | M1: NamaUsaha | N1: NoWhatsapp | O1: PesanWhatsapp
A2: 759724529202804 | B2: R11 | C2: 120241465022560200 | D2: Custom-Deriano-Baru | E2: 46072 | F2: 1162 | G2: 37772.897 | H2: 44 | I2: 50729 | J2: 7 | K2: 451 | L2: 0 | M2: Deriano | O2: *Laporan Jasa Iklan UMKM* 📅 19-02-2026 👨‍💼 Data Klient KampanyeId: 120241465022560200 Nama: *Deriano* 📊 Performa Iklan Jangkauan: 1162 Hasil: *7 klik Whatsapp* Video Ditonton: 451 Komentar: 0 Linkklik: 44 Catatan: Hasil = Jumlah klik whatsapp jumlahnya suka berbeda dengan real Whatsapp masuk. Semoga banyak yang DEAL ya Kak! Mau konsultasi? Langsung balas aja chatnya, mimin siap membantu.😊 | P2: Gagal: Data tidak lengkap
A3: 174904221976312 | B3: R10 | C3: 120230030877630694 | D3: ON-CV.BAGUS DAN-31072025+30-6281357754513-ext 0702-30 - R3 1902 Rusdian | E3: 46072 | F3: 445 | G3: 28713.542 | H3: 14 | I3: 16539 | J3: 3 | K3: 1 | L3: 0 | M3: CV.BAGUS DAN | N3: 6281357754513 | O3: *Laporan Jasa Iklan UMKM* 📅 19-02-2026 👨‍💼 Data Klient KampanyeId: 120230030877630694 Nama: *CV.BAGUS DAN* 📊 Performa Iklan Jangkauan: 445 Hasil: *3 klik Whatsapp* Video Ditonton: 1 Komentar: 0 Linkklik: 14 Catatan: Hasil = Jumlah klik whatsapp jumlahnya suka berbeda dengan real Whatsapp masuk. Semoga banyak yang DEAL ya Kak! Mau konsultasi? Langsung balas aja chatnya, mimin siap membantu.😊 | P3: Gagal: {"status":404,"message":"WhatsApp account doesn't exist!","data":false}
A4: 174904221976312 | B4: R10 | C4: 120230494969540694 | D4: ON-Yono motor-11082025+5-6287701349406-1602-5 | E4: 46072 | F4: 2546 | G4: 5107.1061 | H4: 89 | I4: 14877 | J4: 0 | K4: 100 | L4: 0 | M4: Yono motor | N4: 6287701349406 | O4: *Laporan Jasa Iklan UMKM* 📅 19-02-2026 👨‍💼 Data Klient KampanyeId: 120230494969540694 Nama: *Yono motor* 📊 Performa Iklan Jangkauan: 2546 Hasil: *0 klik Whatsapp* Video Ditonton: 100 Komentar: 0 Linkklik: 89 Catatan: Hasil = Jumlah klik whatsapp jumlahnya suka berbeda dengan real Whatsapp masuk. Semoga banyak yang DEAL ya Kak! Mau konsultasi? Langsung balas aja chatnya, mimin siap membantu.😊 | P4: Gagal: {"status":404,"message":"WhatsApp account doesn't exist!","data":false}
A5: 174904221976312 | B5: R10 | C5: 120230878618490694 | D5: ON-Rumah Sehat-16082025+30-6282166986254-ext 2601-30 - R1 1302 Rusdian | E5: 46072 | F5: 720 | G5: 18311.688 | H5: 42 | I5: 15510 | J5: 8 | K5: 333 | L5: 0 | M5: Rumah Sehat | N5: 6282166986254 | O5: *Laporan Jasa Iklan UMKM* 📅 19-02-2026 👨‍💼 Data Klient KampanyeId: 120230878618490694 Nama: *Rumah Sehat* 📊 Performa Iklan Jangkauan: 720 Hasil: *8 klik Whatsapp* Video Ditonton: 333 Komentar: 0 Linkklik: 42 Catatan: Hasil = Jumlah klik whatsapp jumlahnya suka berbeda dengan real Whatsapp masuk. Semoga banyak yang DEAL ya Kak! Mau konsultasi? Langsung balas aja chatnya, mimin siap membantu.😊 | P5: Gagal: {"status":404,"message":"WhatsApp account doesn't exist!","data":false}
A6: 174904221976312 | B6: R10 | C6: 120231473177720694 | D6: ON-Nizam Traveling-27082025+5-6285361118289-ext: 0402-30 - R4 1902 Rusdian | E6: 46072 | F6: 776 | G6: 18846.523 | H6: 26 | I6: 15718 | J6: 1 | K6: 12 | L6: 0 | M6: Nizam Traveling | N6: 6285361118289 | O6: *Laporan Jasa Iklan UMKM* 📅 19-02-2026 👨‍💼 Data Klient KampanyeId: 120231473177720694 Nama: *Nizam Traveling* 📊 Performa Iklan Jangkauan: 776 Hasil: *1 klik Whatsapp* Video Ditonton: 12 Komentar: 0 Linkklik: 26 Catatan: Hasil = Jumlah klik whatsapp jumlahnya suka berbeda dengan real Whatsapp masuk. Semoga banyak yang DEAL ya Kak! Mau konsultasi? Langsung balas aja chatnya, mimin siap membantu.😊 | P6: Gagal: {"status":404,"message":"WhatsApp account doesn't exist!","data":false}
A7: 174904221976312 | B7: R10 | C7: 120232493664810694 | D7: ON-Rumah Sehat-11092025+5-6281316122975-TT1709-ext 1202-5 | E7: 46072 | F7: 642 | G7: 18053.061 | H7: 17 | I7: 13269 | J7: 2 | K7: 219 | L7: 0 | M7: Rumah Sehat | N7: 6281316122975 | O7: *Laporan Jasa Iklan UMKM* 📅 19-02-2026 👨‍💼 Data Klient KampanyeId: 120232493664810694 Nama: *Rumah Sehat* 📊 Performa Iklan Jangkauan: 642 Hasil: *2 klik Whatsapp* Video Ditonton: 219 Komentar: 0 Linkklik: 17 Catatan: Hasil = Jumlah klik whatsapp jumlahnya suka berbeda dengan real Whatsapp masuk. Semoga banyak yang DEAL ya Kak! Mau konsultasi? Langsung balas aja chatnya, mimin siap membantu.😊 | P7: Gagal: {"status":404,"message":"WhatsApp account doesn't exist!","data":false}
A8: 174904221976312 | B8: R10 | C8: 120234436313700694 | D8: ON-Maniaka Catering-21102025+20-6281246072868-TT2410-ext 1002-20 - R3 1702 Rusdian | E8: 46072 | F8: 531 | G8: 26602.564 | H8: 29 | I8: 16600 | J8: 4 | K8: 178 | L8: 0 | M8: Maniaka Catering | N8: 6281246072868 | O8: *Laporan Jasa Iklan UMKM* 📅 19-02-2026 👨‍💼 Data Klient KampanyeId: 120234436313700694 Nama: *Maniaka Catering* 📊 Performa Iklan Jangkauan: 531 Hasil: *4 klik Whatsapp* Video Ditonton: 178 Komentar: 0 Linkklik: 29 Catatan: Hasil = Jumlah klik whatsapp jumlahnya suka berbeda dengan real Whatsapp masuk. Semoga banyak yang DEAL ya Kak! Mau konsultasi? Langsung balas aja chatnya, mimin siap membantu.😊 | P8: Gagal: {"status":404,"message":"WhatsApp account doesn't exist!","data":false}
A9: 174904221976312 | B9: R10 | C9: 120236224250950694 | D9: ON-Bimbel Antusias-20112025+10-6285292365257-TT2211-ext 0802-14 - R3 1502 Rusdian | E9: 46072 | F9: 599 | G9: 18508.527 | H9: 9 | I9: 11938 | J9: 0 | K9: 0 | L9: 0 | M9: Bimbel Antusias | N9: 6285292365257 | O9: *Laporan Jasa Iklan UMKM* 📅 19-02-2026 👨‍💼 Data Klient KampanyeId: 120236224250950694 Nama: *Bimbel Antusias* 📊 Performa Iklan Jangkauan: 599 Hasil: *0 klik Whatsapp* Video Ditonton: 0 Komentar: 0 Linkklik: 9 Catatan: Hasil = Jumlah klik whatsapp jumlahnya suka berbeda dengan real Whatsapp masuk. Semoga banyak yang DEAL ya Kak! Mau konsultasi? Langsung balas aja chatnya, mimin siap membantu.😊 | P9: Gagal: {"status":404,"message":"WhatsApp account doesn't exist!","data":false}
A10: 174904221976312 | B10: R10 | C10: 120238476998550694 | D10: ON-PT Garuda-05012026+5-6282261184459-TT0701 - ext 0602-14 - R3 1502 Rusdian | E10: 46072 | F10: 300 | G10: 59108.911 | H10: 8 | I10: 17910 | J10: 2 | K10: 0 | L10: 0 | M10: PT Garuda | N10: 6282261184459 | O10: *Laporan Jasa Iklan UMKM* 📅 19-02-2026 👨‍💼 Data Klient KampanyeId: 120238476998550694 Nama: *PT Garuda* 📊 Performa Iklan Jangkauan: 300 Hasil: *2 klik Whatsapp* Video Ditonton: 0 Komentar: 0 Linkklik: 8 Catatan: Hasil = Jumlah klik whatsapp jumlahnya suka berbeda dengan real Whatsapp masuk. Semoga banyak yang DEAL ya Kak! Mau konsultasi? Langsung balas aja chatnya, mimin siap membantu.😊 | P10: Gagal: {"status":404,"message":"WhatsApp account doesn't exist!","data":false}
A11: 174904221976312 | B11: R10 | C11: 120238645880620694 | D11: ON-kredit toko-11012026+5-6282286712200-TT1101-ext 1602-5 | E11: 46072 | F11: 730 | G11: 17933.404 | H11: 47 | I11: 16965 | J11: 7 | K11: 183 | L11: 0 | M11: kredit toko | N11: 6282286712200 | O11: *Laporan Jasa Iklan UMKM* 📅 19-02-2026 👨‍💼 Data Klient KampanyeId: 120238645880620694 Nama: *kredit toko* 📊 Performa Iklan Jangkauan: 730 Hasil: *7 klik Whatsapp* Video Ditonton: 183 Komentar: 0 Linkklik: 47 Catatan: Hasil = Jumlah klik whatsapp jumlahnya suka berbeda dengan real Whatsapp masuk. Semoga banyak yang DEAL ya Kak! Mau konsultasi? Langsung balas aja chatnya, mimin siap membantu.😊 | P11: Gagal: {"status":404,"message":"WhatsApp account doesn't exist!","data":false}
A12: 174904221976312 | B12: R10 | C12: 120238672136120694 | D12: ON-king auto-09012026+5-62895603690686-TT1201-ext 1902-7 | E12: 46072 | F12: 1011 | G12: 14898.998 | H12: 43 | I12: 17849 | J12: 0 | K12: 439 | L12: 0 | M12: king auto | N12: 62895603690686 | O12: *Laporan Jasa Iklan UMKM* 📅 19-02-2026 👨‍💼 Data Klient KampanyeId: 120238672136120694 Nama: *king auto* 📊 Performa Iklan Jangkauan: 1011 Hasil: *0 klik Whatsapp* Video Ditonton: 439 Komentar: 0 Linkklik: 43 Catatan: Hasil = Jumlah klik whatsapp jumlahnya suka berbeda dengan real Whatsapp masuk. Semoga banyak yang DEAL ya Kak! Mau konsultasi? Langsung balas aja chatnya, mimin siap membantu.😊 | P12: Gagal: {"status":404,"message":"WhatsApp account doesn't exist!","data":false}
A13: 174904221976312 | B13: R10 | C13: 120238965258630694 | D13: ON-Deler Honda-19012026+5-6287861389777-TT2001-ext 1802-7 | E13: 46072 | F13: 714 | G13: 20434.62 | H13: 63 | I13: 16409 | J13: 11 | K13: 2 | L13: 3 | M13: Deler Honda | N13: 6287861389777 | O13: *Laporan Jasa Iklan UMKM* 📅 19-02-2026 👨‍💼 Data Klient KampanyeId: 120238965258630694 Nama: *Deler Honda* 📊 Performa Iklan Jangkauan: 714 Hasil: *11 klik Whatsapp* Video Ditonton: 2 Komentar: 3 Linkklik: 63 Catatan: Hasil = Jumlah klik whatsapp jumlahnya suka berbeda dengan real Whatsapp masuk. Semoga banyak yang DEAL ya Kak! Mau konsultasi? Langsung balas aja chatnya, mimin siap membantu.😊 | P13: Gagal: {"status":404,"message":"WhatsApp account doesn't exist!","data":false}
A14: 174904221976312 | B14: R10 | C14: 120239034771370694 | D14: ON-Kegiatan AMT-20012026+30-6281904501876-TT2201 - R6 1302 Rusdian | E14: 46072 | F14: 617 | G14: 18818.316 | H14: 22 | I14: 12740 | J14: 2 | K14: 0 | L14: 0 | M14: Kegiatan AMT | N14: 6281904501876 | O14: *Laporan Jasa Iklan UMKM* 📅 19-02-2026 👨‍💼 Data Klient KampanyeId: 120239034771370694 Nama: *Kegiatan AMT* 📊 Performa Iklan Jangkauan: 617 Hasil: *2 klik Whatsapp* Video Ditonton: 0 Komentar: 0 Linkklik: 22 Catatan: Hasil = Jumlah klik whatsapp jumlahnya suka berbeda dengan real Whatsapp masuk. Semoga banyak yang DEAL ya Kak! Mau konsultasi? Langsung balas aja chatnya, mimin siap membantu.😊 | P14: Gagal: {"status":404,"message":"WhatsApp account doesn't exist!","data":false}
... A45: 206726568613432 | B45: R04 | C45: 120235983090370554 | D45: ON-Wiris Variasi-05042025+7-6282242925264-ext: 2211-10 | E45: 46072 | F45: 2133 | G45: 7280.5195 | H45: 75 | I45: 16818 | J45: 1 | K45: 687 | L45: 0 | M45: Wiris Variasi | N45: 6282242925264 | O45: *Laporan Jasa Iklan UMKM* 📅 19-02-2026 👨‍💼 Data Klient KampanyeId: 120235983090370554 Nama: *Wiris Variasi* 📊 Performa Iklan Jangkauan: 2133 Hasil: *1 klik Whatsapp* Video Ditonton: 687 Komentar: 0 Linkklik: 75 Catatan: Hasil = Jumlah klik whatsapp jumlahnya suka berbeda dengan real Whatsapp masuk. Semoga banyak yang DEAL ya Kak! Mau konsultasi? Langsung balas aja chatnya, mimin siap membantu.😊 | P45: Gagal: {"status":404,"message":"WhatsApp account doesn't exist!","data":false}

Sheet LinkWhatsappLaporan
A1: Link Whatsapp
A2: =HYPERLINK( "https://wa.me/"& 'Performa Iklan'!N1& "?text="& _xludf.ENCODEURL('Performa Iklan'!O1), "Kirim WhatsApp" ) -> #NAME?
A3: =HYPERLINK( "https://wa.me/"& 'Performa Iklan'!N2& "?text="& _xludf.ENCODEURL('Performa Iklan'!O2), "Kirim WhatsApp" ) -> #NAME?
A4: =HYPERLINK( "https://wa.me/"& 'Performa Iklan'!N2& "?text="& _xludf.ENCODEURL('Performa Iklan'!O2), "Kirim WhatsApp" ) -> #NAME?
A5: =HYPERLINK( "https://wa.me/"& 'Performa Iklan'!N3& "?text="& _xludf.ENCODEURL('Performa Iklan'!O3), "Kirim WhatsApp" ) -> #NAME?
A6: =HYPERLINK( "https://wa.me/"& 'Performa Iklan'!N4& "?text="& _xludf.ENCODEURL('Performa Iklan'!O4), "Kirim WhatsApp" ) -> #NAME?
A7: =HYPERLINK( "https://wa.me/"& 'Performa Iklan'!N5& "?text="& _xludf.ENCODEURL('Performa Iklan'!O5), "Kirim WhatsApp" ) -> #NAME?
A8: =HYPERLINK( "https://wa.me/"& 'Performa Iklan'!N6& "?text="& _xludf.ENCODEURL('Performa Iklan'!O6), "Kirim WhatsApp" ) -> #NAME?
A9: =HYPERLINK( "https://wa.me/"& 'Performa Iklan'!N7& "?text="& _xludf.ENCODEURL('Performa Iklan'!O7), "Kirim WhatsApp" ) -> #NAME?
A10: =HYPERLINK( "https://wa.me/"& 'Performa Iklan'!N8& "?text="& _xludf.ENCODEURL('Performa Iklan'!O8), "Kirim WhatsApp" ) -> #NAME?
A11: =HYPERLINK( "https://wa.me/"& 'Performa Iklan'!N9& "?text="& _xludf.ENCODEURL('Performa Iklan'!O9), "Kirim WhatsApp" ) -> #NAME?
A12: =HYPERLINK( "https://wa.me/"& 'Performa Iklan'!N10& "?text="& _xludf.ENCODEURL('Performa Iklan'!O10), "Kirim WhatsApp" ) -> #NAME?
A13: =HYPERLINK( "https://wa.me/"& 'Performa Iklan'!N11& "?text="& _xludf.ENCODEURL('Performa Iklan'!O11), "Kirim WhatsApp" ) -> #NAME?
A14: =HYPERLINK( "https://wa.me/"& 'Performa Iklan'!N12& "?text="& _xludf.ENCODEURL('Performa Iklan'!O12), "Kirim WhatsApp" ) -> #NAME?
A15: =HYPERLINK( "https://wa.me/"& 'Performa Iklan'!N13& "?text="& _xludf.ENCODEURL('Performa Iklan'!O13), "Kirim WhatsApp" ) -> #NAME?
... A149: =HYPERLINK( "https://wa.me/"& 'Performa Iklan'!N147& "?text="& _xludf.ENCODEURL('Performa Iklan'!O147), "Kirim WhatsApp" ) -> #NAME?

Sheet Performa Iklan Klien By Usia
A1: AkunIklanId | B1: NamaAkun | C1: KampanyeId | D1: Nama Usaha | E1: Whatsapp | F1: Tanggal | G1: Reach | H1: Usia | I1: CPM | J1: LinkKlik | K1: Spend | L1: KlikWA | M1: VideoView | N1: Komentar | O1: Nama Kampanye
A2: 759724529202804 | B2: R11 | C2: 120229046011260200 | D2: Abadi Tehnik | E2: 6285711667433 | F2: 45832 | G2: 52 | H2: 18-24 | I2: 9283.3333 | J2: 1 | K2: 557 | L2: 0 | M2: 0 | N2: 0 | O2: ON-Abadi Tehnik-21062025+5-6285711667433
A3: 759724529202804 | B3: R11 | C3: 120229046011260200 | D3: Abadi Tehnik | E3: 6285711667433 | F3: 45832 | G3: 217 | H3: 25-34 | I3: 9277.1084 | J3: 4 | K3: 2310 | L3: 0 | M3: 0 | N3: 0 | O3: ON-Abadi Tehnik-21062025+5-6285711667433
A4: 759724529202804 | B4: R11 | C4: 120229046011260200 | D4: Abadi Tehnik | E4: 6285711667433 | F4: 45832 | G4: 328 | H4: 35-44 | I4: 10936.986 | J4: 3 | K4: 3992 | L4: 0 | M4: 0 | N4: 0 | O4: ON-Abadi Tehnik-21062025+5-6285711667433
A5: 759724529202804 | B5: R11 | C5: 120229046011260200 | D5: Abadi Tehnik | E5: 6285711667433 | F5: 45832 | G5: 252 | H5: 45-54 | I5: 11962.838 | J5: 6 | K5: 3541 | L5: 1 | M5: 0 | N5: 0 | O5: ON-Abadi Tehnik-21062025+5-6285711667433
A6: 759724529202804 | B6: R11 | C6: 120229046011260200 | D6: Abadi Tehnik | E6: 6285711667433 | F6: 45832 | G6: 47 | H6: 55-64 | I6: 15775.51 | J6: 1 | K6: 773 | L6: 0 | M6: 0 | N6: 0 | O6: ON-Abadi Tehnik-21062025+5-6285711667433
A7: 759724529202804 | B7: R11 | C7: 120229046011260200 | D7: Abadi Tehnik | E7: 6285711667433 | F7: 45832 | G7: 11 | H7: 65+ | I7: 6545.4545 | J7: 0 | K7: 72 | L7: 0 | M7: 0 | N7: 0 | O7: ON-Abadi Tehnik-21062025+5-6285711667433
A8: 759724529202804 | B8: R11 | C8: 120229044952270200 | D8: Alfie salon | E8: 6285775986977 | F8: 45832 | G8: 41 | H8: 18-24 | I8: 13304.348 | J8: 0 | K8: 612 | L8: 0 | M8: 0 | N8: 0 | O8: ON-Alfie salon-19062025+5-6285775986977 - Salin
A9: 759724529202804 | B9: R11 | C9: 120229044952270200 | D9: Alfie salon | E9: 6285775986977 | F9: 45832 | G9: 57 | H9: 25-34 | I9: 62578.125 | J9: 0 | K9: 4005 | L9: 0 | M9: 0 | N9: 0 | O9: ON-Alfie salon-19062025+5-6285775986977 - Salin
A10: 759724529202804 | B10: R11 | C10: 120229044952270200 | D10: Alfie salon | E10: 6285775986977 | F10: 45832 | G10: 75 | H10: 35-44 | I10: 54269.663 | J10: 2 | K10: 4830 | L10: 0 | M10: 0 | N10: 0 | O10: ON-Alfie salon-19062025+5-6285775986977 - Salin
A11: 759724529202804 | B11: R11 | C11: 120229044952270200 | D11: Alfie salon | E11: 6285775986977 | F11: 45832 | G11: 38 | H11: 45-54 | I11: 41878.049 | J11: 0 | K11: 1717 | L11: 0 | M11: 0 | N11: 0 | O11: ON-Alfie salon-19062025+5-6285775986977 - Salin
A12: 759724529202804 | B12: R11 | C12: 120229044952270200 | D12: Alfie salon | E12: 6285775986977 | F12: 45832 | G12: 26 | H12: 55-64 | I12: 51428.571 | J12: 1 | K12: 1440 | L12: 0 | M12: 0 | N12: 0 | O12: ON-Alfie salon-19062025+5-6285775986977 - Salin
A13: 759724529202804 | B13: R11 | C13: 120229044952270200 | D13: Alfie salon | E13: 6285775986977 | F13: 45832 | G13: 18 | H13: 65+ | I13: 77105.263 | J13: 0 | K13: 1465 | L13: 0 | M13: 0 | N13: 0 | O13: ON-Alfie salon-19062025+5-6285775986977 - Salin
... A132: 174904221976312 | B132: R10 | C132: 120226464082810694 | D132: Yuzef homestay | E132: 628988759290 | F132: 45832 | G132: 20 | H132: 65+ | I132: 33230.769 | J132: 4 | K132: 864 | L132: 0 | M132: 3 | N132: 0 | O132: ON-Yuzef homestay-11062025+13-628988759290
A133: 174904221976312 | B133: R10 | C133: 120226351656870694 | D133: Rodrimar Aifunan Fresku | F133: 45832 | G133: 1428 | H133: 18-24 | I133: 1319.9728 | J133: 18 | K133: 1943 | L133: 0 | M133: 84 | N133: 0 | O133: ON-Rodrimar Aifunan Fresku-16052025+14-67077619002-Ilham - 2 - Copy
A134: 174904221976312 | B134: R10 | C134: 120226351656870694 | D134: Rodrimar Aifunan Fresku | F134: 45832 | G134: 1600 | H134: 25-34 | I134: 1786.6667 | J134: 23 | K134: 3082 | L134: 0 | M134: 148 | N134: 0 | O134: ON-Rodrimar Aifunan Fresku-16052025+14-67077619002-Ilham - 2 - Copy
A135: 174904221976312 | B135: R10 | C135: 120226351656870694 | D135: Rodrimar Aifunan Fresku | F135: 45832 | G135: 1416 | H135: 35-44 | I135: 2511.7574 | J135: 26 | K135: 4059 | L135: 0 | M135: 205 | N135: 0 | O135: ON-Rodrimar Aifunan Fresku-16052025+14-67077619002-Ilham - 2 - Copy
A136: 174904221976312 | B136: R10 | C136: 120226351656870694 | D136: Rodrimar Aifunan Fresku | F136: 45832 | G136: 552 | H136: 45-54 | I136: 3138.3855 | J136: 9 | K136: 1905 | L136: 0 | M136: 62 | N136: 0 | O136: ON-Rodrimar Aifunan Fresku-16052025+14-67077619002-Ilham - 2 - Copy
A137: 174904221976312 | B137: R10 | C137: 120226351656870694 | D137: Rodrimar Aifunan Fresku | F137: 45832 | G137: 120 | H137: 55-64 | I137: 3176.8707 | J137: 5 | K137: 467 | L137: 0 | M137: 13 | N137: 0 | O137: ON-Rodrimar Aifunan Fresku-16052025+14-67077619002-Ilham - 2 - Copy
A138: 174904221976312 | B138: R10 | C138: 120226351656870694 | D138: Rodrimar Aifunan Fresku | F138: 45832 | G138: 94 | H138: 65+ | I138: 2410.7143 | J138: 3 | K138: 270 | L138: 0 | M138: 9 | N138: 0 | O138: ON-Rodrimar Aifunan Fresku-16052025+14-67077619002-Ilham - 2 - Copy
A139: 174904221976312 | B139: R10 | C139: 120225924609850694 | D139: Amanah Interior | E139: 6282183184641 | F139: 45832 | G139: 15 | H139: 18-24 | I139: 9533.3333 | J139: 0 | K139: 143 | L139: 0 | M139: 0 | N139: 0 | O139: OFF- Amanah Interior-21052025+5-6282183184641 -ilham - NEW
A140: 174904221976312 | B140: R10 | C140: 120225924609850694 | D140: Amanah Interior | E140: 6282183184641 | F140: 45832 | G140: 100 | H140: 25-34 | I140: 20194.245 | J140: 0 | K140: 2807 | L140: 0 | M140: 0 | N140: 0 | O140: OFF- Amanah Interior-21052025+5-6282183184641 -ilham - NEW
A141: 174904221976312 | B141: R10 | C141: 120225924609850694 | D141: Amanah Interior | E141: 6282183184641 | F141: 45832 | G141: 112 | H141: 35-44 | I141: 18987.654 | J141: 3 | K141: 3076 | L141: 0 | M141: 0 | N141: 0 | O141: OFF- Amanah Interior-21052025+5-6282183184641 -ilham - NEW
A142: 174904221976312 | B142: R10 | C142: 120225924609850694 | D142: Amanah Interior | E142: 6282183184641 | F142: 45832 | G142: 89 | H142: 45-54 | I142: 36603.448 | J142: 7 | K142: 4246 | L142: 0 | M142: 1 | N142: 0 | O142: OFF- Amanah Interior-21052025+5-6282183184641 -ilham - NEW
A143: 174904221976312 | B143: R10 | C143: 120225924609850694 | D143: Amanah Interior | E143: 6282183184641 | F143: 45832 | G143: 41 | H143: 55-64 | I143: 34695.652 | J143: 5 | K143: 1596 | L143: 0 | M143: 0 | N143: 0 | O143: OFF- Amanah Interior-21052025+5-6282183184641 -ilham - NEW
A144: 174904221976312 | B144: R10 | C144: 120225924609850694 | D144: Amanah Interior | E144: 6282183184641 | F144: 45832 | G144: 8 | H144: 65+ | I144: 10888.889 | J144: 0 | K144: 98 | L144: 0 | M144: 0 | N144: 0 | O144: OFF- Amanah Interior-21052025+5-6282183184641 -ilham - NEW
A145: 174904221976312 | B145: R10 | C145: 120225732846460694 | D145: SMA Madina | E145: 6281348555887 | F145: 45832 | G145: 137 | H145: 25-34 | I145: 9556.962 | J145: 6 | K145: 1510 | L145: 0 | M145: 35 | N145: 0 | O145: ON-SMA Madina-29052025+20-6281348555887
A146: 174904221976312 | B146: R10 | C146: 120225732846460694 | D146: SMA Madina | E146: 6281348555887 | F146: 45832 | G146: 464 | H146: 35-44 | I146: 12599.634 | J146: 17 | K146: 6892 | L146: 0 | M146: 151 | N146: 0 | O146: ON-SMA Madina-29052025+20-6281348555887
A147: 174904221976312 | B147: R10 | C147: 120225732846460694 | D147: SMA Madina | E147: 6281348555887 | F147: 45832 | G147: 164 | H147: 45-54 | I147: 18453.608 | J147: 5 | K147: 3580 | L147: 0 | M147: 58 | N147: 0 | O147: ON-SMA Madina-29052025+20-6281348555887
A148: 174904221976312 | B148: R10 | C148: 120225732846460694 | D148: SMA Madina | E148: 6281348555887 | F148: 45832 | G148: 10 | H148: 55-64 | I148: 85833.333 | J148: 1 | K148: 1030 | L148: 0 | M148: 5 | N148: 0 | O148: ON-SMA Madina-29052025+20-6281348555887
A149: 174904221976312 | B149: R10 | C149: 120225732846460694 | D149: SMA Madina | E149: 6281348555887 | F149: 45832 | G149: 12 | H149: 65+ | I149: 5875 | J149: 3 | K149: 94 | L149: 0 | M149: 4 | N149: 0 | O149: ON-SMA Madina-29052025+20-6281348555887
A150: 174904221976312 | B150: R10 | C150: 120225575002440694 | D150: Toko Emas Sembiring | E150: 6281263113266 | F150: 45832 | G150: 39 | H150: 18-24 | I150: 6375 | J150: 2 | K150: 306 | L150: 0 | M150: 0 | N150: 1 | O150: ON-Toko Emas Sembiring-15052025+30-6281263113266-Ilham - 2 - RCVR
... A286: 174904221976312 | B286: R10 | C286: 120226464082810694 | D286: Yuzef homestay | E286: 628988759290 | F286: 45832 | G286: 20 | H286: 65+ | I286: 33269.231 | J286: 4 | K286: 865 | L286: 0 | M286: 3 | N286: 0 | O286: ON-Yuzef homestay-11062025+13-628988759290
A287: 174904221976312 | B287: R10 | C287: 120226351656870694 | D287: Rodrimar Aifunan Fresku | F287: 45832 | G287: 1428 | H287: 18-24 | I287: 1318.8602 | J287: 18 | K287: 1944 | L287: 0 | M287: 84 | N287: 0 | O287: ON-Rodrimar Aifunan Fresku-16052025+14-67077619002-Ilham - 2 - Copy
